started with pid 31274
Traceback (most recent call last):
  File "htemp.py", line 93, in <module>
    daemon_runner.do_action()
  File "/usr/lib/python2.7/dist-packages/daemon/runner.py", line 186, in do_action
    func(self)
  File "/usr/lib/python2.7/dist-packages/daemon/runner.py", line 131, in _start
    self.app.run()
  File "htemp.py", line 82, in run
    VALUES(?,?,?)''' % self.db.TABLE_NAME, (i, i, epoch_time))
sqlite3.OperationalError: disk I/O error
